Failure # 1 (occurred at 2021-01-11_22-01-57)
Traceback (most recent call last):
  File "/usr/local/lib/python3.6/dist-packages/ray/tune/trial_runner.py", line 519, in _process_trial
    result = self.trial_executor.fetch_result(trial)
  File "/usr/local/lib/python3.6/dist-packages/ray/tune/ray_trial_executor.py", line 497, in fetch_result
    result = ray.get(trial_future[0], timeout=DEFAULT_GET_TIMEOUT)
  File "/usr/local/lib/python3.6/dist-packages/ray/worker.py", line 1379, in get
    raise value.as_instanceof_cause()
ray.exceptions.RayTaskError(TuneError): [36mray::ImplicitFunc.train()[39m (pid=589, ip=172.28.0.2)
  File "python/ray/_raylet.pyx", line 463, in ray._raylet.execute_task
  File "python/ray/_raylet.pyx", line 415, in ray._raylet.execute_task.function_executor
  File "/usr/local/lib/python3.6/dist-packages/ray/tune/trainable.py", line 183, in train
    result = self.step()
  File "/usr/local/lib/python3.6/dist-packages/ray/tune/function_runner.py", line 366, in step
    self._report_thread_runner_error(block=True)
  File "/usr/local/lib/python3.6/dist-packages/ray/tune/function_runner.py", line 513, in _report_thread_runner_error
    .format(err_tb_str)))
ray.tune.error.TuneError: Trial raised an exception. Traceback:
[36mray::ImplicitFunc.train()[39m (pid=589, ip=172.28.0.2)
  File "/usr/local/lib/python3.6/dist-packages/ray/tune/function_runner.py", line 248, in run
    self._entrypoint()
  File "/usr/local/lib/python3.6/dist-packages/ray/tune/function_runner.py", line 316, in entrypoint
    self._status_reporter.get_checkpoint())
  File "/usr/local/lib/python3.6/dist-packages/ray/tune/function_runner.py", line 575, in _trainable_func
    output = fn()
  File "<ipython-input-20-bacbc8a3e3bf>", line 44, in run_training
NameError: name 'device' is not defined

